2022-08-19 16:31:58,668 : CRITICAL : Unhandled error in Deferred:
2022-08-19 16:31:58,701 : CRITICAL : 
Traceback (most recent call last):
  File "C:\Users\user\anaconda3\lib\site-packages\twisted\internet\defer.py", line 1660, in _inlineCallbacks
    result = current_context.run(gen.send, result)
  File "C:\Users\user\anaconda3\lib\site-packages\scrapy\crawler.py", line 102, in crawl
    self.engine = self._create_engine()
  File "C:\Users\user\anaconda3\lib\site-packages\scrapy\crawler.py", line 116, in _create_engine
    return ExecutionEngine(self, lambda _: self.stop())
  File "C:\Users\user\anaconda3\lib\site-packages\scrapy\core\engine.py", line 84, in __init__
    self.scraper = Scraper(crawler)
  File "C:\Users\user\anaconda3\lib\site-packages\scrapy\core\scraper.py", line 75, in __init__
    self.itemproc = itemproc_cls.from_crawler(crawler)
  File "C:\Users\user\anaconda3\lib\site-packages\scrapy\middleware.py", line 59, in from_crawler
    return cls.from_settings(crawler.settings, crawler)
  File "C:\Users\user\anaconda3\lib\site-packages\scrapy\middleware.py", line 40, in from_settings
    mwcls = load_object(clspath)
  File "C:\Users\user\anaconda3\lib\site-packages\scrapy\utils\misc.py", line 61, in load_object
    mod = import_module(module)
  File "C:\Users\user\anaconda3\lib\importlib\__init__.py", line 127, in import_module
    return _bootstrap._gcd_import(name[level:], package, level)
  File "<frozen importlib._bootstrap>", line 1030, in _gcd_import
  File "<frozen importlib._bootstrap>", line 1007, in _find_and_load
  File "<frozen importlib._bootstrap>", line 986, in _find_and_load_unlocked
  File "<frozen importlib._bootstrap>", line 680, in _load_unlocked
  File "<frozen importlib._bootstrap_external>", line 850, in exec_module
  File "<frozen importlib._bootstrap>", line 228, in _call_with_frames_removed
  File "C:\project\webCrawl\webCrawl\pipelines.py", line 8, in <module>
    import pymysql
ModuleNotFoundError: No module named 'pymysql'
2022-08-19 16:42:42,700 : CRITICAL : Unhandled error in Deferred:
2022-08-19 16:42:42,731 : CRITICAL : 
Traceback (most recent call last):
  File "C:\Users\user\anaconda3\lib\site-packages\twisted\internet\defer.py", line 1660, in _inlineCallbacks
    result = current_context.run(gen.send, result)
  File "C:\Users\user\anaconda3\lib\site-packages\scrapy\crawler.py", line 102, in crawl
    self.engine = self._create_engine()
  File "C:\Users\user\anaconda3\lib\site-packages\scrapy\crawler.py", line 116, in _create_engine
    return ExecutionEngine(self, lambda _: self.stop())
  File "C:\Users\user\anaconda3\lib\site-packages\scrapy\core\engine.py", line 84, in __init__
    self.scraper = Scraper(crawler)
  File "C:\Users\user\anaconda3\lib\site-packages\scrapy\core\scraper.py", line 75, in __init__
    self.itemproc = itemproc_cls.from_crawler(crawler)
  File "C:\Users\user\anaconda3\lib\site-packages\scrapy\middleware.py", line 59, in from_crawler
    return cls.from_settings(crawler.settings, crawler)
  File "C:\Users\user\anaconda3\lib\site-packages\scrapy\middleware.py", line 40, in from_settings
    mwcls = load_object(clspath)
  File "C:\Users\user\anaconda3\lib\site-packages\scrapy\utils\misc.py", line 61, in load_object
    mod = import_module(module)
  File "C:\Users\user\anaconda3\lib\importlib\__init__.py", line 127, in import_module
    return _bootstrap._gcd_import(name[level:], package, level)
  File "<frozen importlib._bootstrap>", line 1030, in _gcd_import
  File "<frozen importlib._bootstrap>", line 1007, in _find_and_load
  File "<frozen importlib._bootstrap>", line 986, in _find_and_load_unlocked
  File "<frozen importlib._bootstrap>", line 680, in _load_unlocked
  File "<frozen importlib._bootstrap_external>", line 850, in exec_module
  File "<frozen importlib._bootstrap>", line 228, in _call_with_frames_removed
  File "C:\project\webCrawl\webCrawl\pipelines.py", line 8, in <module>
    import pymysql
ModuleNotFoundError: No module named 'pymysql'
2022-08-19 16:44:22,718 : CRITICAL : Unhandled error in Deferred:
2022-08-19 16:44:22,718 : CRITICAL : 
Traceback (most recent call last):
  File "C:\Users\user\anaconda3\lib\site-packages\pymysql\connections.py", line 613, in connect
    sock = socket.create_connection(
  File "C:\Users\user\anaconda3\lib\socket.py", line 844, in create_connection
    raise err
  File "C:\Users\user\anaconda3\lib\socket.py", line 832, in create_connection
    sock.connect(sa)
ConnectionRefusedError: [WinError 10061] 無法連線，因為目標電腦拒絕連線。

During handling of the above exception, another exception occurred:

Traceback (most recent call last):
  File "C:\Users\user\anaconda3\lib\site-packages\twisted\internet\defer.py", line 1660, in _inlineCallbacks
    result = current_context.run(gen.send, result)
  File "C:\Users\user\anaconda3\lib\site-packages\scrapy\crawler.py", line 102, in crawl
    self.engine = self._create_engine()
  File "C:\Users\user\anaconda3\lib\site-packages\scrapy\crawler.py", line 116, in _create_engine
    return ExecutionEngine(self, lambda _: self.stop())
  File "C:\Users\user\anaconda3\lib\site-packages\scrapy\core\engine.py", line 84, in __init__
    self.scraper = Scraper(crawler)
  File "C:\Users\user\anaconda3\lib\site-packages\scrapy\core\scraper.py", line 75, in __init__
    self.itemproc = itemproc_cls.from_crawler(crawler)
  File "C:\Users\user\anaconda3\lib\site-packages\scrapy\middleware.py", line 59, in from_crawler
    return cls.from_settings(crawler.settings, crawler)
  File "C:\Users\user\anaconda3\lib\site-packages\scrapy\middleware.py", line 41, in from_settings
    mw = create_instance(mwcls, settings, crawler)
  File "C:\Users\user\anaconda3\lib\site-packages\scrapy\utils\misc.py", line 172, in create_instance
    instance = objcls(*args, **kwargs)
  File "C:\project\webCrawl\webCrawl\pipelines.py", line 14, in __init__
    self.connect = pymysql.connect(
  File "C:\Users\user\anaconda3\lib\site-packages\pymysql\connections.py", line 353, in __init__
    self.connect()
  File "C:\Users\user\anaconda3\lib\site-packages\pymysql\connections.py", line 664, in connect
    raise exc
pymysql.err.OperationalError: (2003, "Can't connect to MySQL server on 'localhost' ([WinError 10061] 無法連線，因為目標電腦拒絕連線。)")
2022-08-23 08:50:47,079 : CRITICAL : Unhandled error in Deferred:
2022-08-23 08:50:47,126 : CRITICAL : 
Traceback (most recent call last):
  File "C:\Users\user\anaconda3\lib\site-packages\pymysql\connections.py", line 613, in connect
    sock = socket.create_connection(
  File "C:\Users\user\anaconda3\lib\socket.py", line 844, in create_connection
    raise err
  File "C:\Users\user\anaconda3\lib\socket.py", line 832, in create_connection
    sock.connect(sa)
ConnectionRefusedError: [WinError 10061] 無法連線，因為目標電腦拒絕連線。

During handling of the above exception, another exception occurred:

Traceback (most recent call last):
  File "C:\Users\user\anaconda3\lib\site-packages\twisted\internet\defer.py", line 1660, in _inlineCallbacks
    result = current_context.run(gen.send, result)
  File "C:\Users\user\anaconda3\lib\site-packages\scrapy\crawler.py", line 102, in crawl
    self.engine = self._create_engine()
  File "C:\Users\user\anaconda3\lib\site-packages\scrapy\crawler.py", line 116, in _create_engine
    return ExecutionEngine(self, lambda _: self.stop())
  File "C:\Users\user\anaconda3\lib\site-packages\scrapy\core\engine.py", line 84, in __init__
    self.scraper = Scraper(crawler)
  File "C:\Users\user\anaconda3\lib\site-packages\scrapy\core\scraper.py", line 75, in __init__
    self.itemproc = itemproc_cls.from_crawler(crawler)
  File "C:\Users\user\anaconda3\lib\site-packages\scrapy\middleware.py", line 59, in from_crawler
    return cls.from_settings(crawler.settings, crawler)
  File "C:\Users\user\anaconda3\lib\site-packages\scrapy\middleware.py", line 41, in from_settings
    mw = create_instance(mwcls, settings, crawler)
  File "C:\Users\user\anaconda3\lib\site-packages\scrapy\utils\misc.py", line 172, in create_instance
    instance = objcls(*args, **kwargs)
  File "C:\project\webCrawl\webCrawl\pipelines.py", line 14, in __init__
    self.connect = pymysql.connect(
  File "C:\Users\user\anaconda3\lib\site-packages\pymysql\connections.py", line 353, in __init__
    self.connect()
  File "C:\Users\user\anaconda3\lib\site-packages\pymysql\connections.py", line 664, in connect
    raise exc
pymysql.err.OperationalError: (2003, "Can't connect to MySQL server on 'localhost' ([WinError 10061] 無法連線，因為目標電腦拒絕連線。)")
2022-08-23 08:59:36,446 : CRITICAL : Unhandled error in Deferred:
2022-08-23 08:59:36,477 : CRITICAL : 
Traceback (most recent call last):
  File "C:\Users\user\anaconda3\lib\site-packages\pymysql\connections.py", line 613, in connect
    sock = socket.create_connection(
  File "C:\Users\user\anaconda3\lib\socket.py", line 844, in create_connection
    raise err
  File "C:\Users\user\anaconda3\lib\socket.py", line 832, in create_connection
    sock.connect(sa)
ConnectionRefusedError: [WinError 10061] 無法連線，因為目標電腦拒絕連線。

During handling of the above exception, another exception occurred:

Traceback (most recent call last):
  File "C:\Users\user\anaconda3\lib\site-packages\twisted\internet\defer.py", line 1660, in _inlineCallbacks
    result = current_context.run(gen.send, result)
  File "C:\Users\user\anaconda3\lib\site-packages\scrapy\crawler.py", line 102, in crawl
    self.engine = self._create_engine()
  File "C:\Users\user\anaconda3\lib\site-packages\scrapy\crawler.py", line 116, in _create_engine
    return ExecutionEngine(self, lambda _: self.stop())
  File "C:\Users\user\anaconda3\lib\site-packages\scrapy\core\engine.py", line 84, in __init__
    self.scraper = Scraper(crawler)
  File "C:\Users\user\anaconda3\lib\site-packages\scrapy\core\scraper.py", line 75, in __init__
    self.itemproc = itemproc_cls.from_crawler(crawler)
  File "C:\Users\user\anaconda3\lib\site-packages\scrapy\middleware.py", line 59, in from_crawler
    return cls.from_settings(crawler.settings, crawler)
  File "C:\Users\user\anaconda3\lib\site-packages\scrapy\middleware.py", line 41, in from_settings
    mw = create_instance(mwcls, settings, crawler)
  File "C:\Users\user\anaconda3\lib\site-packages\scrapy\utils\misc.py", line 172, in create_instance
    instance = objcls(*args, **kwargs)
  File "C:\project\eprocurement-notifier\webCrawl\pipelines.py", line 14, in __init__
    self.connect = pymysql.connect(
  File "C:\Users\user\anaconda3\lib\site-packages\pymysql\connections.py", line 353, in __init__
    self.connect()
  File "C:\Users\user\anaconda3\lib\site-packages\pymysql\connections.py", line 664, in connect
    raise exc
pymysql.err.OperationalError: (2003, "Can't connect to MySQL server on 'localhost' ([WinError 10061] 無法連線，因為目標電腦拒絕連線。)")
